Workbook

Sheet Summary
B1: Banking Transaction Management System (BTMS)
B2: Database Testing - Manual (INSERT / UPDATE validation)
B4: Prepared by | C4: Abdallah Ahmed Meaad - QA / QC Engineer (Manual & Automation Testing) - Tel: 01022656255
B5: Test date | C5: 2026-08-15
B6: Environment | C6: MySQL 8.0.46 (Linux, case-sensitive names), STRICT mode - real btms_db from btms-db.sql
B7: System under test | C7: btms_db (btms-db.sql): 7 tables, 6 FKs,
B8: LinkedIn | C8: https://www.linkedin.com/in/abdallah-meaad
B9: Portfolio | C9: https://abdallahmeaad.github.io/My_CV
B11: 1. Execution summary
B12: Metric | C12: Value
B13: Total test cases | C13: =COUNTA('Test Cases'!$A$5:$A$107) -> 103
B14: Passed | C14: =COUNTIF('Test Cases'!$L$5:$L$167,"Pass") -> 68
B15: Failed | C15: =COUNTIF('Test Cases'!$L$5:$L$167,"Fail") -> 34
B16: Blocked | C16: =COUNTIF('Test Cases'!$L$5:$L$167,"Blocked") -> 1
B17: Not run | C17: =COUNTIF('Test Cases'!$L$5:$L$167,"Not Run") -> 0
B18: Pass rate | C18: =IFERROR(C14/C13,0) -> 0.66019417
B19: Total weight (BRD sizing) | C19: =SUM('Test Cases'!$F$5:$F$107) -> 159
B20: Weighted pass score | C20: =SUMIFS('Test Cases'!$F$5:$F$107,'Test Cases'!$L$5:$L$107,"Pass") -> 102
B21: Weighted pass rate | C21: =IFERROR(C20/C19,0) -> 0.64150943
B22: Total defects | C22: =COUNTA('Bug Reports'!$A$5:$A$62) -> 17
B23: Release recommendation | C23: =IF(AND(C15=0,COUNTIFS('Bug Reports'!$C$5:$C$62,"Critical",'Bug Reports'!$N$5:$N$62,"Open")=0),"GO","NO-GO") -> NO-GO
B25: 2. Results by module
B26: Module | C26: Total | D26: Pass | E26: Fail | F26: Blocked | G26: Pass rate
B27: FR-1 Customers | C27: =COUNTIF('Test Cases'!$B$5:$B$107,B27) -> 19 | D27: =COUNTIFS('Test Cases'!$B$5:$B$107,$B27,'Test Cases'!$L$5:$L$107,"Pass") -> 12 | E27: =COUNTIFS('Test Cases'!$B$5:$B$107,$B27,'Test Cases'!$L$5:$L$107,"Fail") -> 7 | F27: =COUNTIFS('Test Cases'!$B$5:$B$107,$B27,'Test Cases'!$L$5:$L$107,"Blocked") -> 0 | G27: =IFERROR(D27/C27,0) -> 0.63157895
B28: FR-2 Accounts | C28: =COUNTIF('Test Cases'!$B$5:$B$107,B28) -> 15 | D28: =COUNTIFS('Test Cases'!$B$5:$B$107,$B28,'Test Cases'!$L$5:$L$107,"Pass") -> 11 | E28: =COUNTIFS('Test Cases'!$B$5:$B$107,$B28,'Test Cases'!$L$5:$L$107,"Fail") -> 4 | F28: =COUNTIFS('Test Cases'!$B$5:$B$107,$B28,'Test Cases'!$L$5:$L$107,"Blocked") -> 0 | G28: =IFERROR(D28/C28,0) -> 0.73333333
B29: FR-3 Transactions | C29: =COUNTIF('Test Cases'!$B$5:$B$107,B29) -> 29 | D29: =COUNTIFS('Test Cases'!$B$5:$B$107,$B29,'Test Cases'!$L$5:$L$107,"Pass") -> 17 | E29: =COUNTIFS('Test Cases'!$B$5:$B$107,$B29,'Test Cases'!$L$5:$L$107,"Fail") -> 12 | F29: =COUNTIFS('Test Cases'!$B$5:$B$107,$B29,'Test Cases'!$L$5:$L$107,"Blocked") -> 0 | G29: =IFERROR(D29/C29,0) -> 0.5862069
B30: FR-4 Categories | C30: =COUNTIF('Test Cases'!$B$5:$B$107,B30) -> 9 | D30: =COUNTIFS('Test Cases'!$B$5:$B$107,$B30,'Test Cases'!$L$5:$L$107,"Pass") -> 8 | E30: =COUNTIFS('Test Cases'!$B$5:$B$107,$B30,'Test Cases'!$L$5:$L$107,"Fail") -> 1 | F30: =COUNTIFS('Test Cases'!$B$5:$B$107,$B30,'Test Cases'!$L$5:$L$107,"Blocked") -> 0 | G30: =IFERROR(D30/C30,0) -> 0.88888889
B31: FR-5 Fees | C31: =COUNTIF('Test Cases'!$B$5:$B$107,B31) -> 15 | D31: =COUNTIFS('Test Cases'!$B$5:$B$107,$B31,'Test Cases'!$L$5:$L$107,"Pass") -> 7 | E31: =COUNTIFS('Test Cases'!$B$5:$B$107,$B31,'Test Cases'!$L$5:$L$107,"Fail") -> 8 | F31: =COUNTIFS('Test Cases'!$B$5:$B$107,$B31,'Test Cases'!$L$5:$L$107,"Blocked") -> 0 | G31: =IFERROR(D31/C31,0) -> 0.46666667
B32: FR-6 Branches/Employees | C32: =COUNTIF('Test Cases'!$B$5:$B$107,B32) -> 10 | D32: =COUNTIFS('Test Cases'!$B$5:$B$107,$B32,'Test Cases'!$L$5:$L$107,"Pass") -> 8 | E32: =COUNTIFS('Test Cases'!$B$5:$B$107,$B32,'Test Cases'!$L$5:$L$107,"Fail") -> 1 | F32: =COUNTIFS('Test Cases'!$B$5:$B$107,$B32,'Test Cases'!$L$5:$L$107,"Blocked") -> 1 | G32: =IFERROR(D32/C32,0) -> 0.8
B33: NFR Structural | C33: =COUNTIF('Test Cases'!$B$5:$B$107,B33) -> 6 | D33: =COUNTIFS('Test Cases'!$B$5:$B$107,$B33,'Test Cases'!$L$5:$L$107,"Pass") -> 5 | E33: =COUNTIFS('Test Cases'!$B$5:$B$107,$B33,'Test Cases'!$L$5:$L$107,"Fail") -> 1 | F33: =COUNTIFS('Test Cases'!$B$5:$B$107,$B33,'Test Cases'!$L$5:$L$107,"Blocked") -> 0 | G33: =IFERROR(D33/C33,0) -> 0.83333333
B35: 3. Defects by severity
B36: Severity | C36: Count
B37: Critical | C37: =COUNTIF('Bug Reports'!$C$5:$C$62,B37) -> 3
B38: High | C38: =COUNTIF('Bug Reports'!$C$5:$C$62,B38) -> 7
B39: Medium | C39: =COUNTIF('Bug Reports'!$C$5:$C$62,B39) -> 6
B40: Low | C40: =COUNTIF('Bug Reports'!$C$5:$C$62,B40) -> 1
B42: 4. Assumptions used (the BRD is silent on these)
B43: A-01 | C43: Daily transfer limit is below 4,000,000 (value not defined in the BRD).
B44: A-02 | C44: An 'external transfer' is a transfer between accounts of different customers.
B45: A-03 | C45: Fee formula/rate is not defined in the BRD; only the 10% cap is tested.
...

Sheet Test Cases
A1: BTMS - Manual Test Cases (Database Testing: INSERT / UPDATE)
A2: Prepared by Abdallah Ahmed Meaad | QA / QC Engineer | Environment: MySQL 8.0.46 - real btms_db (btms-db.sql, dump of MySQL 8.0.43) | Executed 2026-08-15
A4: TC ID | B4: Module (BRD) | C4: Test Title | D4: Type | E4: Priority | F4: Weight | G4: Preconditions | H4: Manual Test Steps | I4: SQL to Execute | J4: Expected Result | K4: Actual Result | L4: Status | M4: Bug ID | N4: Tested By | O4: Test Date
A5: TC-CUS-01 | B5: FR-1 Customers | C5: Insert a valid customer | D5: Positive | E5: High | F5: 1 | G5: Database btms_db created from the 'DB Scripts' sheet; baseline seed data loaded (see 'DB Seed Data'). | H5: 1. Open the MySQL client and run: USE btms_db; 2. Run: START TRANSACTION; 3. Run the test statement (see SQL column). 4. Run the verification SELECT (see SQL column) and note the result. 5. Run: ROLLBACK; (keeps the baseline data clean for the next test) | I5: START TRANSACTION; INSERT INTO customers (full_name,date_of_birth,email,phone) VALUES ('Abdallah Meaad','1992-01-01','test.user@example.com','01022656255'); SELECT COUNT(*) FROM customers WHERE email='test.user@example.com'; ROLLBACK; | J5: Statement is accepted; row count = 1 | K5: row count = 1 | L5: Pass | M5: - | N5: Abdallah Ahmed Meaad | O5: 2026-08-15
A6: TC-CUS-02 | B6: FR-1 Customers | C6: Insert customer with duplicate email | D6: Negative | E6: High | F6: 1 | G6: Database btms_db created from the 'DB Scripts' sheet; baseline seed data loaded (see 'DB Seed Data'). | H6: 1. Open the MySQL client and run: USE btms_db; 2. Run: START TRANSACTION; 3. Run the test statement (see SQL column). 4. Note whether the statement is rejected with an error. 5. Run: ROLLBACK; (keeps the baseline data clean for the next test) | I6: START TRANSACTION; INSERT INTO customers (full_name,date_of_birth,email,phone) VALUES ('Abdallah Meaad','1992-01-01','ahmed.hassan@example.com','01022656255'); ROLLBACK; | J6: Statement is rejected with an error (constraint / trigger) | K6: Rejected - 1062: Duplicate entry 'ahmed.hassan@example.com' for key 'customers.email' | L6: Pass | M6: - | N6: Abdallah Ahmed Meaad | O6: 2026-08-15
A7: TC-CUS-03 | B7: FR-1 Customers | C7: Duplicate email differing only by letter case | D7: Edge | E7: Medium | F7: 1 | G7: Database btms_db created from the 'DB Scripts' sheet; baseline seed data loaded (see 'DB Seed Data'). | H7: 1. Open the MySQL client and run: USE btms_db; 2. Run: START TRANSACTION; 3. Run the test statement (see SQL column). 4. Note whether the statement is rejected with an error. 5. Run: ROLLBACK; (keeps the baseline data clean for the next test) | I7: START TRANSACTION; INSERT INTO customers (full_name,date_of_birth,email,phone) VALUES ('Abdallah Meaad','1992-01-01','AHMED.HASSAN@EXAMPLE.COM','01022656255'); ROLLBACK; | J7: Statement is rejected with an error (constraint / trigger) | K7: Rejected - 1062: Duplicate entry 'AHMED.HASSAN@EXAMPLE.COM' for key 'customers.email' | L7: Pass | M7: - | N7: Abdallah Ahmed Meaad | O7: 2026-08-15
A8: TC-CUS-04 | B8: FR-1 Customers | C8: Insert customer with NULL full_name | D8: Negative | E8: High | F8: 1 | G8: Database btms_db created from the 'DB Scripts' sheet; baseline seed data loaded (see 'DB Seed Data'). | H8: 1. Open the MySQL client and run: USE btms_db; 2. Run: START TRANSACTION; 3. Run the test statement (see SQL column). 4. Note whether the statement is rejected with an error. 5. Run: ROLLBACK; (keeps the baseline data clean for the next test) | I8: START TRANSACTION; INSERT INTO customers (full_name,date_of_birth,email,phone) VALUES (NULL,'1992-01-01','test.user@example.com','01000000000'); ROLLBACK; | J8: Statement is rejected with an error (constraint / trigger) | K8: Rejected - 1048: Column 'full_name' cannot be null | L8: Pass | M8: - | N8: Abdallah Ahmed Meaad | O8: 2026-08-15
A9: TC-CUS-05 | B9: FR-1 Customers | C9: Insert customer with NULL date_of_birth | D9: Negative | E9: High | F9: 1 | G9: Database btms_db created from the 'DB Scripts' sheet; baseline seed data loaded (see 'DB Seed Data'). | H9: 1. Open the MySQL client and run: USE btms_db; 2. Run: START TRANSACTION; 3. Run the test statement (see SQL column). 4. Note whether the statement is rejected with an error. 5. Run: ROLLBACK; (keeps the baseline data clean for the next test) | I9: START TRANSACTION; INSERT INTO customers (full_name,date_of_birth,email,phone) VALUES ('Abdallah Meaad',NULL,'test.user@example.com','01022656255'); ROLLBACK; | J9: Statement is rejected with an error (constraint / trigger) | K9: Rejected - 1048: Column 'date_of_birth' cannot be null | L9: Pass | M9: - | N9: Abdallah Ahmed Meaad | O9: 2026-08-15
A10: TC-CUS-06 | B10: FR-1 Customers | C10: Insert customer with NULL email | D10: Negative | E10: High | F10: 1 | G10: Database btms_db created from the 'DB Scripts' sheet; baseline seed data loaded (see 'DB Seed Data'). | H10: 1. Open the MySQL client and run: USE btms_db; 2. Run: START TRANSACTION; 3. Run the test statement (see SQL column). 4. Note whether the statement is rejected with an error. 5. Run: ROLLBACK; (keeps the baseline data clean for the next test) | I10: START TRANSACTION; INSERT INTO customers (full_name,date_of_birth,email,phone) VALUES ('Abdallah Meaad','1992-01-01',NULL,'01022656255'); ROLLBACK; | J10: Statement is rejected with an error (constraint / trigger) | K10: Rejected - 1048: Column 'email' cannot be null | L10: Pass | M10: - | N10: Abdallah Ahmed Meaad | O10: 2026-08-15
A11: TC-CUS-07 | B11: FR-1 Customers | C11: Insert customer with NULL phone | D11: Negative | E11: High | F11: 1 | G11: Database btms_db created from the 'DB Scripts' sheet; baseline seed data loaded (see 'DB Seed Data'). | H11: 1. Open the MySQL client and run: USE btms_db; 2. Run: START TRANSACTION; 3. Run the test statement (see SQL column). 4. Note whether the statement is rejected with an error. 5. Run: ROLLBACK; (keeps the baseline data clean for the next test) | I11: START TRANSACTION; INSERT INTO customers (full_name,date_of_birth,email,phone) VALUES ('Abdallah Meaad','1992-01-01','test.user@example.com',NULL); ROLLBACK; | J11: Statement is rejected with an error (constraint / trigger) | K11: Rejected - 1048: Column 'phone' cannot be null | L11: Pass | M11: - | N11: Abdallah Ahmed Meaad | O11: 2026-08-15
A12: TC-CUS-08 | B12: FR-1 Customers | C12: Phone containing letters ('0101abc4567') | D12: Negative | E12: High | F12: 1 | G12: Database btms_db created from the 'DB Scripts' sheet; baseline seed data loaded (see 'DB Seed Data'). | H12: 1. Open the MySQL client and run: USE btms_db; 2. Run: START TRANSACTION; 3. Run the test statement (see SQL column). 4. Note whether the statement is rejected with an error. 5. Run: ROLLBACK; (keeps the baseline data clean for the next test) | I12: START TRANSACTION; INSERT INTO customers (full_name,date_of_birth,email,phone) VALUES ('Abdallah Meaad','1992-01-01','test.user@example.com','0101abc4567'); ROLLBACK; | J12: Statement is rejected with an error (constraint / trigger) Ref: BRD FR-1: phone must contain numeric values only | K12: ACCEPTED - no error raised; rule is not enforced by the database | L12: Fail | M12: BUG-007 | N12: Abdallah Ahmed Meaad | O12: 2026-08-15
A13: TC-CUS-09 | B13: FR-1 Customers | C13: Phone containing symbols ('+20-101-2345') | D13: Negative | E13: High | F13: 1 | G13: Database btms_db created from the 'DB Scripts' sheet; baseline seed data loaded (see 'DB Seed Data'). | H13: 1. Open the MySQL client and run: USE btms_db; 2. Run: START TRANSACTION; 3. Run the test statement (see SQL column). 4. Note whether the statement is rejected with an error. 5. Run: ROLLBACK; (keeps the baseline data clean for the next test) | I13: START TRANSACTION; INSERT INTO customers (full_name,date_of_birth,email,phone) VALUES ('Abdallah Meaad','1992-01-01','test.user@example.com','+20-101-2345'); ROLLBACK; | J13: Statement is rejected with an error (constraint / trigger) Ref: BRD FR-1: numeric values only | K13: ACCEPTED - no error raised; rule is not enforced by the database | L13: Fail | M13: BUG-007 | N13: Abdallah Ahmed Meaad | O13: 2026-08-15
A14: TC-CUS-10 | B14: FR-1 Customers | C14: Phone as empty string | D14: Edge | E14: Medium | F14: 1 | G14: Database btms_db created from the 'DB Scripts' sheet; baseline seed data loaded (see 'DB Seed Data'). | H14: 1. Open the MySQL client and run: USE btms_db; 2. Run: START TRANSACTION; 3. Run the test statement (see SQL column). 4. Note whether the statement is rejected with an error. 5. Run: ROLLBACK; (keeps the baseline data clean for the next test) | I14: START TRANSACTION; INSERT INTO customers (full_name,date_of_birth,email,phone) VALUES ('Abdallah Meaad','1992-01-01','test.user@example.com',''); ROLLBACK; | J14: Statement is rejected with an error (constraint / trigger) Ref: Mandatory field must not be satisfied by an empty string | K14: ACCEPTED - no error raised; rule is not enforced by the database | L14: Fail | M14: BUG-015 | N14: Abdallah Ahmed Meaad | O14: 2026-08-15
A15: TC-CUS-11 | B15: FR-1 Customers | C15: Date of birth in the future (2099-01-01) | D15: Edge | E15: Medium | F15: 1 | G15: Database btms_db created from the 'DB Scripts' sheet; baseline seed data loaded (see 'DB Seed Data'). | H15: 1. Open the MySQL client and run: USE btms_db; 2. Run: START TRANSACTION; 3. Run the test statement (see SQL column). 4. Note whether the statement is rejected with an error. 5. Run: ROLLBACK; (keeps the baseline data clean for the next test) | I15: START TRANSACTION; INSERT INTO customers (full_name,date_of_birth,email,phone) VALUES ('Abdallah Meaad','2099-01-01','test.user@example.com','01022656255'); ROLLBACK; | J15: Statement is rejected with an error (constraint / trigger) Ref: Data-integrity expectation (assumption A-04) | K15: ACCEPTED - no error raised; rule is not enforced by the database | L15: Fail | M15: BUG-016 | N15: Abdallah Ahmed Meaad | O15: 2026-08-15
A16: TC-CUS-12 | B16: FR-1 Customers | C16: Malformed email ('not-an-email') | D16: Edge | E16: Low | F16: 1 | G16: Database btms_db created from the 'DB Scripts' sheet; baseline seed data loaded (see 'DB Seed Data'). | H16: 1. Open the MySQL client and run: USE btms_db; 2. Run: START TRANSACTION; 3. Run the test statement (see SQL column). 4. Note whether the statement is rejected with an error. 5. Run: ROLLBACK; (keeps the baseline data clean for the next test) | I16: START TRANSACTION; INSERT INTO customers (full_name,date_of_birth,email,phone) VALUES ('Abdallah Meaad','1992-01-01','not-an-email','01022656255'); ROLLBACK; | J16: Statement is rejected with an error (constraint / trigger) Ref: Data-quality expectation (assumption A-04) | K16: ACCEPTED - no error raised; rule is not enforced by the database | L16: Fail | M16: BUG-016 | N16: Abdallah Ahmed Meaad | O16: 2026-08-15
... A107: TC-NFR-06 | B107: NFR Structural | C107: Object names follow snake_case (tables) | D107: Structural | E107: Low | F107: 1 | G107: Database btms_db created from the 'DB Scripts' sheet; baseline seed data loaded (see 'DB Seed Data'). | H107: 1. Open the MySQL client and run: USE btms_db; 2. Run: START TRANSACTION; 3. Run the test statement (see SQL column). 4. Run the verification SELECT (see SQL column) and note the result. 5. Run: ROLLBACK; (keeps the baseline data clean for the next test) | I107: START TRANSACTION; SELECT 1; SELECT COUNT(*) FROM information_schema.tables WHERE table_schema=DATABASE() AND BINARY table_name<>BINARY LOWER(table_name); ROLLBACK; | J107: tables not in snake_case = 0 | K107: tables not in snake_case = 0 | L107: Pass | M107: - | N107: Abdallah Ahmed Meaad | O107: 2026-08-15

Sheet Bug Reports
A1: BTMS - Bug Reports
A2: Reported by Abdallah Ahmed Meaad | Reproduce on the baseline seed data | Environment: MySQL 8.0.46 - real btms_db (btms-db.sql)
A4: Bug ID | B4: Title | C4: Severity | D4: Priority | E4: Module | F4: BRD Ref | G4: Related Test Cases | H4: Description | I4: Steps to Reproduce (SQL) | J4: Expected Result | K4: Actual Result | L4: Impact | M4: Suggested Fix | N4: Status | O4: Reported By | P4: Date
A5: BUG-001 | B5: Balances are never updated by Deposit / Withdrawal / Transfer / Bill Payment (balance triggers missing) | C5: Critical | D5: P1 | E5: FR-3 Transactions | F5: FR-2, FR-3, Sec.4, Sec.7 | G5: TC-TRX-01, TC-TRX-02, TC-TRX-03, TC-TRX-04, TC-TRX-22, TC-NFR-05 | H5: The BRD requires balances to update automatically through triggers (Sec.4 and Sec.9 state 2 triggers). The delivered DDL contains no triggers at all, so transactions are stored but never reflected in Accounts.balance. A Pending->Success status update also does not move money. | I5: START TRANSACTION; SELECT balance FROM accounts WHERE account_number = 1001; -- 5000.00 INSERT INTO transactions (sender_account,transaction_type,amount,transaction_status,transaction_date) VALUES (1001,'Deposit',500.00,'Success','2026-10-01'); SELECT balance FROM accounts WHERE account_number = 1001; -- still 5000.00 SELECT COUNT(*) FROM information_schema.triggers WHERE trigger_schema='btms_db'; -- 0 ROLLBACK; | J5: Balance becomes 5500.00 (Withdrawal/Bill Payment decrease it, Transfer moves money between both accounts). At least 2 triggers exist. | K5: TC-TRX-01: balance of 1001 = 5000.00 (expected 5500.00) TC-TRX-02: balance of 1001 = 5000.00 (expected 4800.00) TC-TRX-03: balances 1001|1004 = 5000.00|10000.00 (expected 4000.00|11000.00) TC-TRX-04: balance of 1002 = 2000.00 (expected 1700.00) TC-TRX-22: balance of 1001 = 5000.00 (expected 4900.00) TC-NFR-05: trigger count >= 2 = 0 (expected 1) | L5: Ledger and balances diverge immediately. Every money-movement rule of the system is unusable. Release blocker. | M5: Add AFTER INSERT and AFTER UPDATE triggers on transactions that apply the movement when status = 'Success' | N5: Open | O5: Abdallah Ahmed Meaad | P5: 2026-08-15
A6: BUG-002 | B6: Withdrawal / Transfer / Bill Payment above the available balance is accepted as 'Success' | C6: Critical | D6: P1 | E6: FR-3 Transactions | F6: FR-3, Sec.7 | G6: TC-TRX-15, TC-TRX-16 | H6: BRD: 'Cannot transfer or withdraw more than available balance'. The database accepts a Success withdrawal of 5000 from an account holding 2000, and a transfer from an account holding 0. No validation exists at row level. After BUG-001 is fixed, CHECK(balance >= 0) would only fail with a generic error, so an explicit rule is still required. | I6: START TRANSACTION; INSERT INTO transactions (sender_account,transaction_type,amount,transaction_status,transaction_date) VALUES (1002,'Withdrawal',5000.00,'Success','2026-10-01'); -- balance of 1002 is 2000.00 SELECT transaction_status, amount FROM transactions ORDER BY transaction_id DESC LIMIT 1; -- Success, 5000.00 ROLLBACK; | J6: Insert is rejected with an 'Insufficient balance' error; no Success row is stored. | K6: TC-TRX-15: ACCEPTED - no error raised; rule is not enforced by the database TC-TRX-16: ACCEPTED - no error raised; rule is not enforced by the database | L6: Overdraft / fraud exposure; financial loss; audit failure. | M6: BEFORE INSERT (and BEFORE UPDATE Pending->Success) trigger comparing the sender balance with the amount (trg_transactions_bi / trg_transactions_bu). | N6: Open | O6: Abdallah Ahmed Meaad | P6: 2026-08-15
A7: BUG-003 | B7: Fees are not calculated automatically for transfers or failed transactions | C7: Critical | D7: P1 | E7: FR-5 Fees | F7: FR-5, Sec.4, Sec.7 | G7: TC-FEE-12, TC-FEE-13, TC-NFR-05 | H7: BRD FR-5: 'Auto-calculate fees for transfers and failed transactions' via triggers. Inserting a successful transfer or a failed attempt creates no Fees row. | I7: START TRANSACTION; INSERT INTO transactions (sender_account,receiver_account,transaction_type,amount,transaction_status,transaction_date) VALUES (1001,1004,'Transfer',100.00,'Success','2026-10-01'); SELECT COUNT(*) FROM fees WHERE transaction_id = (SELECT MAX(transaction_id) FROM transactions); -- 0 ROLLBACK; | J7: One 'Transfer Fee' row is generated for the transfer; one 'Failed Transaction Fee' row for a failed attempt. | K7: TC-FEE-12: fees generated for new transfer = 0 (expected 1) TC-FEE-13: fees generated for failed attempt = 0 (expected 1) TC-NFR-05: trigger count >= 2 = 0 (expected 1) | L7: Bank revenue is lost; fee reporting is incomplete. | M7: AFTER INSERT trigger on transactions inserting the fee row (trg_transactions_ai). The fee rate and the definition of 'external' are undefined in the BRD - see Requirements_Review R-02/R-03. | N7: Open | O7: Abdallah Ahmed Meaad | P7: 2026-08-15
A8: BUG-004 | B8: Accounts.balance accepts NULL (insert, omitted value and update) | C8: High | D8: P2 | E8: FR-2 Accounts | F8: FR-2 | G8: TC-ACC-04, TC-ACC-05, TC-ACC-07 | H8: balance is declared 'DECIMAL(15,2) CHECK(balance >= 0)' without NOT NULL. For NULL the CHECK evaluates to UNKNOWN, which SQL treats as satisfied, so the 'mandatory, >= 0' rule of FR-2 is bypassed. | I8: START TRANSACTION; INSERT INTO accounts (customer_id,account_type,balance) VALUES (1,'Savings',NULL); INSERT INTO accounts (customer_id,account_type) VALUES (1,'Savings'); UPDATE accounts SET balance = NULL WHERE account_number = 1001; SELECT account_number, balance FROM accounts WHERE balance IS NULL; ROLLBACK; | J8: All three statements are rejected. | K8: TC-ACC-04: ACCEPTED - no error raised; rule is not enforced by the database TC-ACC-05: ACCEPTED - no error raised; rule is not enforced by the database TC-ACC-07: ACCEPTED - no error raised; rule is not enforced by the database | L8: NULL balances break arithmetic (balance - amount = NULL) and any trigger-based validation. | M8: ALTER TABLE accounts MODIFY balance DECIMAL(15,2) NOT NULL (and keep CHECK(balance >= 0)). | N8: Open | O8: Abdallah Ahmed Meaad | P8: 2026-08-15
A9: BUG-005 | B9: Transactions.amount accepts NULL (CHECK(amount > 0) is bypassed) | C9: High | D9: P2 | E9: FR-3 Transactions | F9: FR-3 | G9: TC-TRX-07 | H9: Same root cause as BUG-004: CHECK on a nullable column passes for NULL. | I9: START TRANSACTION; INSERT INTO transactions (sender_account,transaction_type,amount,transaction_date) VALUES (1001,'Deposit',NULL,'2026-10-01'); SELECT transaction_id, amount FROM transactions WHERE amount IS NULL; ROLLBACK; | J9: Insert is rejected (amount is mandatory and > 0). | K9: TC-TRX-07: ACCEPTED - no error raised; rule is not enforced by the database | L9: Transactions without an amount; balance calculations return NULL. | M9: ALTER TABLE transactions MODIFY amount DECIMAL(15,2) NOT NULL + CHECK(amount > 0). | N9: Open | O9: Abdallah Ahmed Meaad | P9: 2026-08-15
A10: BUG-006 | B10: Fees.amount accepts NULL (CHECK(amount > 0) is bypassed) | C10: High | D10: P2 | E10: FR-5 Fees | F10: FR-5 | G10: TC-FEE-04 | H10: Same root cause as BUG-004. | I10: START TRANSACTION; INSERT INTO fees (transaction_id,fee_type,amount) VALUES (1,'Transfer Fee',NULL); SELECT * FROM fees WHERE amount IS NULL; ROLLBACK; | J10: Insert is rejected (amount is a mandatory field). | K10: TC-FEE-04: ACCEPTED - no error raised; rule is not enforced by the database | L10: Fee totals become unreliable. | M10: ALTER TABLE fees MODIFY amount DECIMAL(10,2) NOT NULL + CHECK(amount > 0). | N10: Open | O10: Abdallah Ahmed Meaad | P10: 2026-08-15
A11: BUG-007 | B11: Customers.phone accepts letters and symbols (numeric-only rule not enforced), on insert and update | C11: High | D11: P2 | E11: FR-1 Customers | F11: FR-1 | G11: TC-CUS-08, TC-CUS-09, TC-CUS-16 | H11: BRD FR-1: 'Phone must contain numeric values only'. phone is a plain VARCHAR(20) with no CHECK. | I11: START TRANSACTION; INSERT INTO customers (full_name,date_of_birth,email,phone) VALUES ('Abdallah Meaad','1992-01-01','t1@example.com','0101abc4567'); INSERT INTO customers (full_name,date_of_birth,email,phone) VALUES ('Abdallah Meaad','1992-01-01','t2@example.com','+20-101-2345'); UPDATE customers SET phone = 'ABC123' WHERE customer_id = 1; SELECT customer_id, phone FROM customers WHERE phone NOT REGEXP '^[0-9]+$'; ROLLBACK; | J11: All three statements are rejected. | K11: TC-CUS-08: ACCEPTED - no error raised; rule is not enforced by the database TC-CUS-09: ACCEPTED - no error raised; rule is not enforced by the database TC-CUS-16: ACCEPTED - no error raised; rule is not enforced by the database | L11: Invalid contact data; SMS/notification failures; KYC/compliance issues. | M11: CHECK (phone REGEXP '^[0-9]+$') on MySQL 8.0.16+; CHECK (phone NOT LIKE '%[^0-9]%' AND LEN(phone) > 0) on SQL Server. | N11: Open | O11: Abdallah Ahmed Meaad | P11: 2026-08-15
A12: BUG-008 | B12: Fee larger than 10% of the transaction amount is accepted (insert and update) | C12: High | D12: P2 | E12: FR-5 Fees | F12: FR-5 | G12: TC-FEE-05, TC-FEE-14 | H12: BRD FR-5: 'Fee cannot exceed 10% of transaction amount'. A fee of 50 on a 100 transaction (50%) is stored, and an existing fee can be raised to 60. | I12: START TRANSACTION; INSERT INTO fees (transaction_id,fee_type,amount) VALUES (1,'Transfer Fee',50.00); -- transaction 1 amount = 100.00 UPDATE fees SET amount = 60.00 WHERE fee_id = 1; SELECT f.fee_id, f.amount, t.amount AS tx_amount FROM fees f JOIN transactions t USING (transaction_id) WHERE f.amount > t.amount*0.10; ROLLBACK; | J12: Both statements are rejected; boundary value 10.00 (exactly 10%) is accepted (TC-FEE-06 passes). | K12: TC-FEE-05: ACCEPTED - no error raised; rule is not enforced by the database TC-FEE-14: ACCEPTED - no error raised; rule is not enforced by the database | L12: Customers can be over-charged; regulatory complaint risk. | M12: BEFORE INSERT / BEFORE UPDATE triggers on fees comparing NEW.amount with transactions.amount * 0.10 (trg_fees_bi / trg_fees_bu). | N12: Open | O12: Abdallah Ahmed Meaad | P12: 2026-08-15
A13: BUG-009 | B13: A Transfer can be inserted without a receiver account | C13: High | D13: P2 | E13: FR-3 Transactions | F13: FR-3 | G13: TC-TRX-17 | H13: BRD: receiver_account is nullable only for withdrawals/deposits. A 'Transfer' with receiver_account = NULL is accepted. | I13: START TRANSACTION; INSERT INTO transactions (sender_account,receiver_account,transaction_type,amount,transaction_status,transaction_date) VALUES (1001,NULL,'Transfer',100.00,'Success','2026-10-01'); SELECT * FROM transactions WHERE transaction_type='Transfer' AND receiver_account IS NULL; ROLLBACK; | J13: Insert is rejected. | K13: TC-TRX-17: ACCEPTED - no error raised; rule is not enforced by the database | L13: Money leaves an account with no destination. | M13: CHECK (transaction_type <> 'Transfer' OR receiver_account IS NOT NULL). | N13: Open | O13: Abdallah Ahmed Meaad | P13: 2026-08-15
A14: BUG-010 | B14: Daily transfer limit is not enforced (and its value is not defined in the BRD) | C14: High | D14: P2 | E14: FR-3 Transactions | F14: FR-3, Sec.7 | G14: TC-TRX-27 | H14: BRD: 'Daily transfer limits enforced via triggers'. A transfer of 4,000,000 is accepted. No limit table/column/constant exists, so the rule is both unimplemented and unspecified. | I14: START TRANSACTION; UPDATE accounts SET balance = 5000000.00 WHERE account_number = 1004; INSERT INTO transactions (sender_account,receiver_account,transaction_type,amount,transaction_status,transaction_date) VALUES (1004,1001,'Transfer',4000000.00,'Success','2026-10-01'); SELECT SUM(amount) FROM transactions WHERE sender_account=1004 AND transaction_date='2026-10-01'; ROLLBACK; | J14: Rejected once the (to be defined) daily limit is exceeded; cumulative transfers of the same day count. | K14: TC-TRX-27: ACCEPTED - no error raised; rule is not enforced by the database | L14: No protection against large/fraudulent transfers. | M14: Product owner must define the limit (assumption A-01 = 1,000,000). Enforce with a BEFORE INSERT trigger summing the sender's same-day transfers (trg_transactions_bi). | N14: Open | O14: Abdallah Ahmed Meaad | P14: 2026-08-15
A15: BUG-011 | B15: Transfer from an account to itself is accepted | C15: Medium | D15: P3 | E15: FR-3 Transactions | F15: FR-3 (implicit) | G15: TC-TRX-18 | H15: sender_account = receiver_account is stored for a Transfer. With balance triggers this would be a no-op that still costs a fee. | I15: START TRANSACTION; INSERT INTO transactions (sender_account,receiver_account,transaction_type,amount,transaction_status,transaction_date) VALUES (1001,1001,'Transfer',100.00,'Success','2026-10-01'); SELECT * FROM transactions WHERE sender_account = receiver_account; ROLLBACK; | J15: Insert is rejected. | K15: TC-TRX-18: ACCEPTED - no error raised; rule is not enforced by the database | L15: Meaningless/fee-generating records; reporting noise. | M15: CHECK (receiver_account IS NULL OR receiver_account <> sender_account). | N15: Open | O15: Abdallah Ahmed Meaad | P15: 2026-08-15
... A21: BUG-017 | B21: Schema gap: no link between Employees and transaction approvals, so the 'cannot delete approver' rule is impossible | C21: Medium | D21: P3 | E21: FR-6 Employees | F21: FR-6 | G21: TC-EMP-06 | H21: BRD FR-6: 'Employee cannot be deleted if responsible for transaction approvals'. No Transactions column or approvals table references Employees, therefore the rule cannot be implemented or tested (DELETE is also outside the INSERT/UPDATE scope). | I21: SELECT column_name FROM information_schema.columns WHERE table_schema='btms_db' AND table_name='transactions'; -- no approved_by / employee_id column exists SELECT COUNT(*) FROM information_schema.referential_constraints WHERE constraint_schema='btms_db' AND referenced_table_name='employees'; -- 0 FKs reference employees | J21: A relationship (e.g. Transactions.approved_by -> Employees.employee_id ON DELETE RESTRICT) exists. | K21: TC-EMP-06: Cannot be designed: no column/table links an employee to a transaction approval (BRD FR-6 rule). Also DELETE is outside the INSERT/UPDATE test scope. | L21: Business rule cannot be enforced. | M21: ADD COLUMN approved_by INT NULL + FOREIGN KEY ... ON DELETE RESTRICT | N21: Open | O21: Abdallah Ahmed Meaad | P21: 2026-08-15

Sheet DB Schema
A1: BTMS - Database Schema (actual btms_db, exported from btms-db.sql - MySQL 8.0.43)
A2: 7 tables | 6 foreign keys | 3 CHECK constraints (accounts_chk_1, transactions_chk_1, fees_chk_1) | 0 triggers | All table names are lower-case snake_case
A4: Table | B4: Column | C4: Data Type | D4: Key | E4: Nullable | F4: Constraint / Default | G4: Related BRD rule
A5: customers | B5: customer_id | C5: INT | D5: PK | E5: No | F5: AUTO_INCREMENT | G5: All PKs auto-incremented
A6: customers | B6: full_name | C6: VARCHAR(100) | E6: No | F6: NOT NULL | G6: FR-1 mandatory
A7: customers | B7: date_of_birth | C7: DATE | E7: No | F7: NOT NULL | G7: FR-1 mandatory
A8: customers | B8: email | C8: VARCHAR(100) | D8: UNIQUE | E8: No | F8: UNIQUE, NOT NULL | G8: FR-1 mandatory, must be unique
A9: customers | B9: phone | C9: VARCHAR(20) | E9: No | F9: NOT NULL (no numeric CHECK) | G9: FR-1 numeric values only -> BUG-007
A10: accounts | B10: account_number | C10: INT | D10: PK | E10: No | F10: AUTO_INCREMENT | G10: FR-2 unique account number
A11: accounts | B11: customer_id | C11: INT | D11: FK | E11: No | F11: FK -> customers(customer_id) | G11: FR-2 customer can have multiple accounts
A12: accounts | B12: account_type | C12: ENUM('Savings','Current','Wallet') | E12: No | F12: NOT NULL | G12: FR-2 account types
A13: accounts | B13: balance | C13: DECIMAL(15,2) | E13: Yes | F13: CHECK(balance >= 0), nullable | G13: FR-2 mandatory, >= 0 -> BUG-004
A14: transaction_categories | B14: category_id | C14: INT | D14: PK | E14: No | F14: AUTO_INCREMENT | G14: FR-4
A15: transaction_categories | B15: category_name | C15: VARCHAR(50) | D15: UNIQUE | E15: No | F15: UNIQUE, NOT NULL | G15: FR-4 mandatory
A16: transactions | B16: transaction_id | C16: INT | D16: PK | E16: No | F16: AUTO_INCREMENT | G16: FR-3
A17: transactions | B17: sender_account | C17: INT | D17: FK | E17: No | F17: FK -> accounts(account_number) | G17: FR-3 sender must exist
A18: transactions | B18: receiver_account | C18: INT | D18: FK | E18: Yes | F18: FK -> accounts(account_number) | G18: FR-3 nullable only for deposit/withdrawal -> BUG-009
A19: transactions | B19: category_id | C19: INT | D19: FK | E19: Yes | F19: FK -> transaction_categories(category_id) | G19: FR-4 one category per transaction
A20: transactions | B20: transaction_type | C20: ENUM('Deposit','Withdrawal','Transfer','Bill Payment') | E20: No | F20: NOT NULL | G20: FR-3 types
A21: transactions | B21: amount | C21: DECIMAL(15,2) | E21: Yes | F21: CHECK(amount > 0), nullable | G21: FR-3 amount > 0 -> BUG-005
A22: transactions | B22: transaction_status | C22: ENUM('Success','Failed','Pending') | E22: Yes | F22: DEFAULT 'Pending' | G22: Sec.7 status must be valid
A23: transactions | B23: transaction_date | C23: DATE | E23: No | F23: NOT NULL | G23: FR-3 mandatory
A24: fees | B24: fee_id | C24: INT | D24: PK | E24: No | F24: AUTO_INCREMENT | G24: FR-5
A25: fees | B25: transaction_id | C25: INT | D25: FK | E25: No | F25: FK -> transactions(transaction_id) | G25: FR-5
A26: fees | B26: fee_type | C26: ENUM('Transfer Fee','Failed Transaction Fee','Over Limit Fee') | E26: No | F26: NOT NULL | G26: FR-5 types
A27: fees | B27: amount | C27: DECIMAL(10,2) | E27: Yes | F27: CHECK(amount > 0), nullable | G27: FR-5 mandatory, <= 10% of transaction -> BUG-006, BUG-008
A28: branches | B28: branch_id | C28: INT | D28: PK | E28: No | F28: AUTO_INCREMENT | G28: FR-6
A29: branches | B29: name | C29: VARCHAR(100) | E29: No | F29: NOT NULL | G29: FR-6 mandatory
A30: branches | B30: location | C30: VARCHAR(100) | E30: Yes | F30: nullable | G30: FR-6 mandatory -> BUG-014
A31: employees | B31: employee_id | C31: INT | D31: PK | E31: No | F31: AUTO_INCREMENT | G31: FR-6
A32: employees | B32: full_name | C32: VARCHAR(100) | E32: No | F32: NOT NULL | G32: FR-6 mandatory
A33: employees | B33: branch_id | C33: INT | D33: FK | E33: No | F33: FK -> branches(branch_id) | G33: FR-6 employees linked to branches

Sheet DB ERD
A1: BTMS - Entity Relationship Diagram (actual btms_db)
A2: Exported from MySQL Workbench. 7 tables, 6 foreign keys, no triggers.
A37: Foreign key | B37: Child table.column | C37: Parent table.column
A38: accounts_ibfk_1 | B38: accounts.customer_id | C38: customers.customer_id
A39: transactions_ibfk_1 | B39: transactions.sender_account | C39: accounts.account_number
A40: transactions_ibfk_2 | B40: transactions.receiver_account | C40: accounts.account_number
A41: transactions_ibfk_3 | B41: transactions.category_id | C41: transaction_categories.category_id
A42: fees_ibfk_1 | B42: fees.transaction_id | C42: transactions.transaction_id
A43: employees_ibfk_1 | B43: employees.branch_id | C43: branches.branch_id

Sheet DB Seed Data
A1: BTMS - Baseline Seed Data
A2: Load this data before executing any test. Every test is wrapped in START TRANSACTION ... ROLLBACK, so the data stays unchanged.
A4: Table: customers (4 rows)
A5: customer_id | B5: full_name | C5: date_of_birth | D5: email | E5: phone
A6: 1 | B6: Ahmed Hassan | C6: 1990-05-14 | D6: ahmed.hassan@example.com | E6: 01012345678
A7: 2 | B7: Sara Ali | C7: 1995-11-02 | D7: sara.ali@example.com | E7: 01123456789
A8: 3 | B8: Omar Khaled | C8: 1988-03-21 | D8: omar.khaled@example.com | E8: 01234567890
A9: 4 | B9: Mona Adel | C9: 2000-07-09 | D9: mona.adel@example.com | E9: 01512345678
A12: Table: accounts (5 rows)
A13: account_number | B13: customer_id | C13: account_type | D13: balance
A14: 1001 | B14: 1 | C14: Savings | D14: 5000
A15: 1002 | B15: 1 | C15: Current | D15: 2000
A16: 1003 | B16: 2 | C16: Wallet | D16: 300
A17: 1004 | B17: 3 | C17: Savings | D17: 10000
A18: 1005 | B18: 4 | C18: Current | D18: 0
A21: Table: transaction_categories (5 rows)
A22: category_id | B22: category_name
A23: 1 | B23: Utilities
A24: 2 | B24: Shopping
A25: 3 | B25: Salary
A26: 4 | B26: Entertainment
A27: 5 | B27: Other
A30: Table: branches (2 rows)
A31: branch_id | B31: name | C31: location
A32: 1 | B32: Cairo Main | C32: Cairo
A33: 2 | B33: Alexandria Corniche | C33: Alexandria
A36: Table: employees (2 rows)
A37: employee_id | B37: full_name | C37: branch_id
A38: 1 | B38: Hany Mostafa | C38: 1
A39: 2 | B39: Nadia Fathy | C39: 2
A42: Table: transactions (3 rows)
A43: transaction_id | B43: sender_account | C43: receiver_account | D43: category_id | E43: transaction_type | F43: amount | G43: transaction_status | H43: transaction_date
A44: 1 | B44: 1001 | C44: 1004 | D44: NULL | E44: Transfer | F44: 100 | G44: Success | H44: 2026-09-01
A45: 2 | B45: 1002 | C45: NULL | D45: 1 | E45: Bill Payment | F45: 50 | G45: Success | H45: 2026-09-02
A46: 3 | B46: 1003 | C46: NULL | D46: NULL | E46: Withdrawal | F46: 20 | G46: Failed | H46: 2026-09-03
A49: Table: fees (2 rows)
A50: fee_id | B50: transaction_id | C50: fee_type | D50: amount
A51: 1 | B51: 1 | C51: Transfer Fee | D51: 2
A52: 2 | B52: 3 | C52: Failed Transaction Fee | D52: 1

Sheet DB Scripts
A1: BTMS - Database Scripts (copy and run in MySQL Workbench / DBeaver / MySQL CLI)
A2: Step 1: run the Schema script -> Step 2: run the Seed script. Both come from the real database export btms-db.sql (MySQL 8.0.43).
A4: SCRIPT 1 - SCHEMA (actual btms_db, unchanged)
A5: -- ============================================================
A6: -- BTMS - Schema exactly as exported from the real database (btms-db.sql)
A7: -- DO NOT FIX: the database is the System Under Test.
A8: -- ============================================================
A9: DROP DATABASE IF EXISTS btms_db;
A10: CREATE DATABASE btms_db CHARACTER SET utf8mb4;
A11: USE btms_db;
A13: CREATE TABLE `customers` (
A14: `customer_id` int NOT NULL AUTO_INCREMENT,
... A126: (2,3,'Failed Transaction Fee',1.00);
